필수 산출물

- 유저스토리(스프린트 백로그) 백로그 하나가 스토리하나
- API설계서
- 





```
Exception in thread django-main-thread:
Traceback (most recent call last):
  File "C:\Users\albei\itpl\itple-contest-api\venv\lib\site-packages\django\urls\resolvers.py", line 600, in url_patterns
    iter(patterns)
TypeError: 'module' object is not iterable

The above exception was the direct cause of the following exception:

Traceback (most recent call last):
  File "c:\users\albei\appdata\local\programs\python\python39\lib\threading.py", line 954, in _bootstrap_inner
    self.run()
  File "c:\users\albei\appdata\local\programs\python\python39\lib\threading.py", line 892, in run
    self._target(*self._args, **self._kwargs)
  File "C:\Users\albei\itpl\itple-contest-api\venv\lib\site-packages\django\utils\autoreload.py", line 64, in wrapper
    fn(*args, **kwargs)
  File "C:\Users\albei\itpl\itple-contest-api\venv\lib\site-packages\django\core\management\commands\runserver.py", line 118, in inner_run
    self.check(display_num_errors=True)
  File "C:\Users\albei\itpl\itple-contest-api\venv\lib\site-packages\django\core\management\base.py", line 419, in check
    all_issues = checks.run_checks(
  File "C:\Users\albei\itpl\itple-contest-api\venv\lib\site-packages\django\core\checks\registry.py", line 76, in run_checks
    new_errors = check(app_configs=app_configs, databases=databases)
  File "C:\Users\albei\itpl\itple-contest-api\venv\lib\site-packages\django\core\checks\urls.py", line 13, in check_url_config
    return check_resolver(resolver)
  File "C:\Users\albei\itpl\itple-contest-api\venv\lib\site-packages\django\core\checks\urls.py", line 23, in check_resolver
    return check_method()
  File "C:\Users\albei\itpl\itple-contest-api\venv\lib\site-packages\django\urls\resolvers.py", line 413, in check
    messages.extend(check_resolver(pattern))
  File "C:\Users\albei\itpl\itple-contest-api\venv\lib\site-packages\django\core\checks\urls.py", line 23, in check_resolver
    return check_method()
  File "C:\Users\albei\itpl\itple-contest-api\venv\lib\site-packages\django\urls\resolvers.py", line 412, in check
    for pattern in self.url_patterns:
  File "C:\Users\albei\itpl\itple-contest-api\venv\lib\site-packages\django\utils\functional.py", line 48, in __get__
    res = instance.__dict__[self.name] = self.func(instance)
  File "C:\Users\albei\itpl\itple-contest-api\venv\lib\site-packages\django\urls\resolvers.py", line 607, in url_patterns
    raise ImproperlyConfigured(msg.format(name=self.urlconf_name)) from e
django.core.exceptions.ImproperlyConfigured: The included URLconf '<module 'contest.urls' from 'C:\\Users\\albei\\itpl\\itple-contest-api\\contest_api\\contest\\urls.py'>' does not appear to have any patterns in it. If you see valid patterns in the file then the issue is probably caused by a circular import.
```

